Workbook

Sheet REKENING UNG
A1: PENERIMA | B1: NOREK | C1: BANK | D1: CABANG
A2: GHOFAR ARIEF RIATMOKO | B2: 4441008575 | C2: UOB | D2: SALATIGA
A3: SEPTIANA TRISNIATI | B3: 4441015369 | C3: UOB | D3: SALATIGA
A4: MUHAMAD ARWANI | B4: 4441008699 | C4: UOB | D4: SALATIGA
A5: ERAWAN PRAYUDA | B5: 4441009237 | C5: UOB | D5: SALATIGA
A6: AZIZ SISWANTO | B6: 3141057039 | C6: UOB | D6: SALATIGA
A7: AMIN | B7: 4131013374 | C7: UOB | D7: SALATIGA
A8: AGUSTINUS DHARIAN TAHTA SUPRIYADI | B8: 4401014084 | C8: UOB | D8: SALATIGA
A9: RISA TOFANTISARI | B9: 5203701439 | C9: UOB | D9: SALATIGA
A10: HANDIKA DENI SINTARA | B10: 4441009253 | C10: UOB | D10: SALATIGA
A11: FATKUR ROHMAN | B11: 4441009415 | C11: UOB | D11: SALATIGA
A12: EDI SUPARMAN | B12: 3141057063 | C12: UOB | D12: SALATIGA
A13: NUR ALI | B13: 4441008478 | C13: UOB | D13: SALATIGA
... A196: Istianingsih | B196: 4443709589 | C196: UOB | D196: SALATIGA
A197: ANDI NURHANDI | B197: 4441008648 | C197: UOB | D197: BANDUNG
A198: EGIN SURYANA | B198: 433701006745530 | C198: BRI | D198: UNIT MARIUK
A199: WAWAN SETIAWAN | B199: 4363700718 | C199: UOB | D199: BANDUNG
A200: ARIFUL MUTAKIN | B200: 2221096209 | C200: BCA | D200: UNGARAN
A201: PUJI SUPRICHATI | B201: 610101018175530 | C201: BRI | D201: UNGARAN
A202: DWI NOFITASARI | B202: 2221073845 | C202: BCA | D202: UNGARAN
A203: TRI RAHMANI | B203: 609401034939531 | C203: BRI | D203: BERGAS
A204: BAGAS AGIL CAHYONO | B204: 4443712601 | C204: UOB | D204: SALATIGA
A205: FAIDATUN ULFA | B205: 4443712458 | C205: UOB | D205: SALATIGA
A206: TRI SUMARTININGSIH | B206: 4443712423 | C206: UOB | D206: SALATIGA
A207: PUTRI SINDORO | B207: 4443712563 | C207: UOB | D207: SALATIGA
A208: ROI KUSUMAWATI | B208: 4443712555 | C208: UOB | D208: SALATIGA
A209: DEVIANA PUTRI RAHAYU | B209: 4443712547 | C209: UOB | D209: SALATIGA
A210: DHIMAS BAYU NUGROHO | B210: 4443712741 | C210: UOB | D210: SALATIGA
A211: RIO ADI CANDRA | B211: 4443712504 | C211: UOB | D211: SALATIGA
A212: ISWANTO | B212: 4443712490 | C212: UOB | D212: SALATIGA
A213: DEDY MAHARDIKA SATRIA | B213: 4443712849 | C213: UOB | D213: SALATIGA
A214: AYUB SEPTIADI PUTRA | B214: 4443712857 | C214: UOB | D214: SALATIGA
A215: ADITYA DWI CHANDRA | B215: 4443712822 | C215: UOB | D215: SALATIGA
A216: AJENG AGUSTIN | B216: 4443712806 | C216: UOB | D216: SALATIGA
... A231: Michael Joshua Eka Putra | B231: 4443709414 | C231: UOB | D231: SALATIGA
A232: RIO ALDI PAMUNGKAS | B232: 7323251081 | C232: UOB | D232: SALATIGA
A233: DAVID D SUPRIATINA | B233: 4443713268 | C233: UOB | D233: SALATIGA
A234: WAKHID | B234: 4443713276 | C234: UOB | D234: SALATIGA
A235: MUSTHAFA ARIF ALMANFALUTHI | B235: 4443713160 | C235: UOB | D235: SALATIGA
A236: ENDY PURNOMO | B236: 4443713187 | C236: UOB | D236: SALATIGA
...

Sheet UM DAN LEMBUR ALL IN JUNI'26
A3: No | B3: NAMA | E3: UM | F3: LEMBUR SABTU | H3: LEMBUR MINGGU | J3: UANG MAKAN | K3: LEMBUR SABTU | L3: LEMBUR MINGGU | M3: INSENTIF | N3: PBLT | O3: REVISI | P3: TOTAL
F4: DUA | G4: FULL | H4: 1/2 HK | I4: L
A5: 1 | B5: HANDIKA DENI SINTARA | C5: ALL IN | D5: =VLOOKUP(B5,'[1]GAJI 25 JULI - 24 AGST 2022'!C$9:D$42,2,0) -> MANDOR SHIFT | J5: =(E5*15000) -> 0 | K5: =(F5*IF(C5="ALL IN",50000,IF(C5="KEPALA SHIFT",52500,IF(C5="KABAG",55000))))+(G5*IF(C5="ALL IN",100000,IF(C5="KEPALA SHIFT",105000,IF(C5="KABAG",110000)))) -> 0 | L5: =(H5*IF(C5="ALL IN",100000,IF(C5="KEPALA SHIFT",105000,IF(C5="KABAG",110000))))+(I5*IF(C5="ALL IN",200000,IF(C5="KEPALA SHIFT",210000,IF(C5="KABAG",220000)))) -> 0 | N5: =CEILING(SUM(K5:L5),100)-SUM(K5:L5) -> 0 | P5: =SUM(J5:O5) -> 0
A6: =A5+1 -> 2 | B6: ERAWAN PRAYUDA | C6: ALL IN | D6: =VLOOKUP(B6,'[1]GAJI 25 JULI - 24 AGST 2022'!C$9:D$42,2,0) -> MANDOR SHIFT | J6: =(E6*15000) -> 0 | K6: =(F6*IF(C6="ALL IN",50000,IF(C6="KEPALA SHIFT",52500,IF(C6="KABAG",55000))))+(G6*IF(C6="ALL IN",100000,IF(C6="KEPALA SHIFT",105000,IF(C6="KABAG",110000)))) -> 0 | L6: =(H6*IF(C6="ALL IN",100000,IF(C6="KEPALA SHIFT",105000,IF(C6="KABAG",110000))))+(I6*IF(C6="ALL IN",200000,IF(C6="KEPALA SHIFT",210000,IF(C6="KABAG",220000)))) -> 0 | N6: =CEILING(SUM(K6:L6),100)-SUM(K6:L6) -> 0 | P6: =SUM(J6:O6) -> 0
A7: =A6+1 -> 3 | B7: AZIZ SISWANTO | C7: ALL IN | D7: =VLOOKUP(B7,'[1]GAJI 25 JULI - 24 AGST 2022'!C$9:D$42,2,0) -> MANDOR SHIFT | J7: =(E7*15000) -> 0 | K7: =(F7*IF(C7="ALL IN",50000,IF(C7="KEPALA SHIFT",52500,IF(C7="KABAG",55000))))+(G7*IF(C7="ALL IN",100000,IF(C7="KEPALA SHIFT",105000,IF(C7="KABAG",110000)))) -> 0 | L7: =(H7*IF(C7="ALL IN",100000,IF(C7="KEPALA SHIFT",105000,IF(C7="KABAG",110000))))+(I7*IF(C7="ALL IN",200000,IF(C7="KEPALA SHIFT",210000,IF(C7="KABAG",220000)))) -> 0 | N7: =CEILING(SUM(K7:L7),100)-SUM(K7:L7) -> 0 | P7: =SUM(J7:O7) -> 0
A8: =A7+1 -> 4 | B8: FATKUR ROHMAN | C8: ALL IN | D8: =VLOOKUP(B8,'[1]GAJI 25 JULI - 24 AGST 2022'!C$9:D$42,2,0) -> MANDOR SHIFT | J8: =(E8*15000) -> 0 | K8: =(F8*IF(C8="ALL IN",50000,IF(C8="KEPALA SHIFT",52500,IF(C8="KABAG",55000))))+(G8*IF(C8="ALL IN",100000,IF(C8="KEPALA SHIFT",105000,IF(C8="KABAG",110000)))) -> 0 | L8: =(H8*IF(C8="ALL IN",100000,IF(C8="KEPALA SHIFT",105000,IF(C8="KABAG",110000))))+(I8*IF(C8="ALL IN",200000,IF(C8="KEPALA SHIFT",210000,IF(C8="KABAG",220000)))) -> 0 | N8: =CEILING(SUM(K8:L8),100)-SUM(K8:L8) -> 0 | P8: =SUM(J8:O8) -> 0
A9: =A8+1 -> 5 | B9: FANDI FABRIAN | C9: ALL IN | D9: =VLOOKUP(B9,'[1]GAJI 25 JULI - 24 AGST 2022'!C$9:D$42,2,0) -> MANDOR SHIFT | J9: =(E9*15000) -> 0 | K9: =(F9*IF(C9="ALL IN",50000,IF(C9="KEPALA SHIFT",52500,IF(C9="KABAG",55000))))+(G9*IF(C9="ALL IN",100000,IF(C9="KEPALA SHIFT",105000,IF(C9="KABAG",110000)))) -> 0 | L9: =(H9*IF(C9="ALL IN",100000,IF(C9="KEPALA SHIFT",105000,IF(C9="KABAG",110000))))+(I9*IF(C9="ALL IN",200000,IF(C9="KEPALA SHIFT",210000,IF(C9="KABAG",220000)))) -> 0 | N9: =CEILING(SUM(K9:L9),100)-SUM(K9:L9) -> 0 | P9: =SUM(J9:O9) -> 0
A10: =A9+1 -> 6 | B10: ANDI SETIAWAN | C10: ALL IN | D10: =VLOOKUP(B10,'[1]GAJI 25 JULI - 24 AGST 2022'!C$9:D$42,2,0) -> MANDOR SHIFT | J10: =(E10*15000) -> 0 | K10: =(F10*IF(C10="ALL IN",50000,IF(C10="KEPALA SHIFT",52500,IF(C10="KABAG",55000))))+(G10*IF(C10="ALL IN",100000,IF(C10="KEPALA SHIFT",105000,IF(C10="KABAG",110000)))) -> 0 | L10: =(H10*IF(C10="ALL IN",100000,IF(C10="KEPALA SHIFT",105000,IF(C10="KABAG",110000))))+(I10*IF(C10="ALL IN",200000,IF(C10="KEPALA SHIFT",210000,IF(C10="KABAG",220000)))) -> 0 | N10: =CEILING(SUM(K10:L10),100)-SUM(K10:L10) -> 0 | P10: =SUM(J10:O10) -> 0
A11: =A10+1 -> 7 | B11: MOHAMMAD NUR MUCHAROM | C11: ALL IN | D11: MANDOR SHIFT | J11: =(E11*15000) -> 0 | K11: =(F11*IF(C11="ALL IN",50000,IF(C11="KEPALA SHIFT",52500,IF(C11="KABAG",55000))))+(G11*IF(C11="ALL IN",100000,IF(C11="KEPALA SHIFT",105000,IF(C11="KABAG",110000)))) -> 0 | L11: =(H11*IF(C11="ALL IN",100000,IF(C11="KEPALA SHIFT",105000,IF(C11="KABAG",110000))))+(I11*IF(C11="ALL IN",200000,IF(C11="KEPALA SHIFT",210000,IF(C11="KABAG",220000)))) -> 0 | N11: =CEILING(SUM(K11:L11),100)-SUM(K11:L11) -> 0 | P11: =SUM(J11:O11) -> 0
A12: =A11+1 -> 8 | B12: GHOFAR ARIEF RIATMOKO | C12: KEPALA SHIFT | D12: =VLOOKUP(B12,'[1]GAJI 25 JULI - 24 AGST 2022'!C$9:D$42,2,0) -> MANDOR SCREEN | J12: =(E12*15000) -> 0 | K12: =(F12*IF(C12="ALL IN",50000,IF(C12="KEPALA SHIFT",52500,IF(C12="KABAG",55000))))+(G12*IF(C12="ALL IN",100000,IF(C12="KEPALA SHIFT",105000,IF(C12="KABAG",110000)))) -> 0 | L12: =(H12*IF(C12="ALL IN",100000,IF(C12="KEPALA SHIFT",105000,IF(C12="KABAG",110000))))+(I12*IF(C12="ALL IN",200000,IF(C12="KEPALA SHIFT",210000,IF(C12="KABAG",220000)))) -> 0 | N12: =CEILING(SUM(K12:L12),100)-SUM(K12:L12) -> 0 | P12: =SUM(J12:O12) -> 0
A13: =A12+1 -> 9 | B13: MUHAMAD ARWANI | C13: ALL IN | D13: =VLOOKUP(B13,'[1]GAJI 25 JULI - 24 AGST 2022'!C$9:D$42,2,0) -> TINTA | J13: =(E13*15000) -> 0 | K13: =(F13*IF(C13="ALL IN",50000,IF(C13="KEPALA SHIFT",52500,IF(C13="KABAG",55000))))+(G13*IF(C13="ALL IN",100000,IF(C13="KEPALA SHIFT",105000,IF(C13="KABAG",110000)))) -> 0 | L13: =(H13*IF(C13="ALL IN",100000,IF(C13="KEPALA SHIFT",105000,IF(C13="KABAG",110000))))+(I13*IF(C13="ALL IN",200000,IF(C13="KEPALA SHIFT",210000,IF(C13="KABAG",220000)))) -> 0 | N13: =CEILING(SUM(K13:L13),100)-SUM(K13:L13) -> 0 | P13: =SUM(J13:O13) -> 0
A14: =A13+1 -> 10 | B14: DWI SETYAWATI | C14: ALL IN | D14: =VLOOKUP(B14,'[1]GAJI 25 JULI - 24 AGST 2022'!C$9:D$42,2,0) -> QC PRINT | J14: =(E14*15000) -> 0 | K14: =(F14*IF(C14="ALL IN",50000,IF(C14="KEPALA SHIFT",52500,IF(C14="KABAG",55000))))+(G14*IF(C14="ALL IN",100000,IF(C14="KEPALA SHIFT",105000,IF(C14="KABAG",110000)))) -> 0 | L14: =(H14*IF(C14="ALL IN",100000,IF(C14="KEPALA SHIFT",105000,IF(C14="KABAG",110000))))+(I14*IF(C14="ALL IN",200000,IF(C14="KEPALA SHIFT",210000,IF(C14="KABAG",220000)))) -> 0 | N14: =CEILING(SUM(K14:L14),100)-SUM(K14:L14) -> 0 | P14: =SUM(J14:O14) -> 0
A15: =A14+1 -> 11 | B15: DEWI NUR FAIYAH | C15: ALL IN | D15: =VLOOKUP(B15,'[1]GAJI 25 JULI - 24 AGST 2022'!C$9:D$42,2,0) -> QC PRINT | J15: =(E15*15000) -> 0 | K15: =(F15*IF(C15="ALL IN",50000,IF(C15="KEPALA SHIFT",52500,IF(C15="KABAG",55000))))+(G15*IF(C15="ALL IN",100000,IF(C15="KEPALA SHIFT",105000,IF(C15="KABAG",110000)))) -> 0 | L15: =(H15*IF(C15="ALL IN",100000,IF(C15="KEPALA SHIFT",105000,IF(C15="KABAG",110000))))+(I15*IF(C15="ALL IN",200000,IF(C15="KEPALA SHIFT",210000,IF(C15="KABAG",220000)))) -> 0 | N15: =CEILING(SUM(K15:L15),100)-SUM(K15:L15) -> 0 | P15: =SUM(J15:O15) -> 0
A16: =A15+1 -> 12 | B16: SANI NUR FAJRIYAH | C16: ALL IN | D16: =VLOOKUP(B16,'[1]GAJI 25 JULI - 24 AGST 2022'!C$9:D$42,2,0) -> IN-OUT | J16: =(E16*15000) -> 0 | K16: =(F16*IF(C16="ALL IN",50000,IF(C16="KEPALA SHIFT",52500,IF(C16="KABAG",55000))))+(G16*IF(C16="ALL IN",100000,IF(C16="KEPALA SHIFT",105000,IF(C16="KABAG",110000)))) -> 0 | L16: =(H16*IF(C16="ALL IN",100000,IF(C16="KEPALA SHIFT",105000,IF(C16="KABAG",110000))))+(I16*IF(C16="ALL IN",200000,IF(C16="KEPALA SHIFT",210000,IF(C16="KABAG",220000)))) -> 0 | N16: =CEILING(SUM(K16:L16),100)-SUM(K16:L16) -> 0 | P16: =SUM(J16:O16) -> 0
A17: =A16+1 -> 13 | B17: RIZKY PRADEVI UTAMI | C17: ALL IN | D17: =VLOOKUP(B17,'[1]GAJI 25 JULI - 24 AGST 2022'!C$9:D$42,2,0) -> ADM | J17: =(E17*15000) -> 0 | K17: =(F17*IF(C17="ALL IN",50000,IF(C17="KEPALA SHIFT",52500,IF(C17="KABAG",55000))))+(G17*IF(C17="ALL IN",100000,IF(C17="KEPALA SHIFT",105000,IF(C17="KABAG",110000)))) -> 0 | L17: =(H17*IF(C17="ALL IN",100000,IF(C17="KEPALA SHIFT",105000,IF(C17="KABAG",110000))))+(I17*IF(C17="ALL IN",200000,IF(C17="KEPALA SHIFT",210000,IF(C17="KABAG",220000)))) -> 0 | N17: =CEILING(SUM(K17:L17),100)-SUM(K17:L17) -> 0 | P17: =SUM(J17:O17) -> 0
A18: =A17+1 -> 14 | B18: ENDANG PURNAMA SARI | C18: ALL IN | D18: GUDANG | J18: =(E18*15000) -> 0 | K18: =(F18*IF(C18="ALL IN",50000,IF(C18="KEPALA SHIFT",52500)))+(G18*IF(C18="ALL IN",100000,IF(C18="KEPALA SHIFT",110000))) -> 0 | L18: =(H18*IF(C18="ALL IN",100000,IF(C18="KEPALA SHIFT",105000)))+(I18*IF(C18="ALL IN",200000,IF(C18="KEPALA SHIFT",210000))) -> 0 | N18: =CEILING(SUM(K18:L18),100)-SUM(K18:L18) -> 0 | P18: =SUM(J18:O18) -> 0
A19: =A18+1 -> 15 | B19: IBNU HAKIM | C19: ALL IN | D19: =VLOOKUP(B19,'[1]GAJI 25 JULI - 24 AGST 2022'!C$9:D$42,2,0) -> SAMPLE | J19: =(E19*15000) -> 0 | K19: =(F19*IF(C19="ALL IN",50000,IF(C19="KEPALA SHIFT",52500,IF(C19="KABAG",55000))))+(G19*IF(C19="ALL IN",100000,IF(C19="KEPALA SHIFT",105000,IF(C19="KABAG",110000)))) -> 0 | L19: =(H19*IF(C19="ALL IN",100000,IF(C19="KEPALA SHIFT",105000,IF(C19="KABAG",110000))))+(I19*IF(C19="ALL IN",200000,IF(C19="KEPALA SHIFT",210000,IF(C19="KABAG",220000)))) -> 0 | N19: =CEILING(SUM(K19:L19),100)-SUM(K19:L19) -> 0 | P19: =SUM(J19:O19) -> 0
A20: =A19+1 -> 16 | B20: AGUS SETIAWAN | C20: ALL IN | D20: =VLOOKUP(B20,'[1]GAJI 25 JULI - 24 AGST 2022'!C$9:D$42,2,0) -> SAMPLE | J20: =(E20*15000) -> 0 | K20: =(F20*IF(C20="ALL IN",50000,IF(C20="KEPALA SHIFT",52500,IF(C20="KABAG",55000))))+(G20*IF(C20="ALL IN",100000,IF(C20="KEPALA SHIFT",105000,IF(C20="KABAG",110000)))) -> 0 | L20: =(H20*IF(C20="ALL IN",100000,IF(C20="KEPALA SHIFT",105000,IF(C20="KABAG",110000))))+(I20*IF(C20="ALL IN",200000,IF(C20="KEPALA SHIFT",210000,IF(C20="KABAG",220000)))) -> 0 | N20: =CEILING(SUM(K20:L20),100)-SUM(K20:L20) -> 0 | P20: =SUM(J20:O20) -> 0
A21: =A20+1 -> 17 | B21: NINA | C21: ALL IN | D21: =VLOOKUP(B21,'[1]GAJI 25 JULI - 24 AGST 2022'!C$9:D$42,2,0) -> SAMPLE | J21: =(E21*15000) -> 0 | K21: =(F21*IF(C21="ALL IN",50000,IF(C21="KEPALA SHIFT",52500,IF(C21="KABAG",55000))))+(G21*IF(C21="ALL IN",100000,IF(C21="KEPALA SHIFT",105000,IF(C21="KABAG",110000)))) -> 0 | L21: =(H21*IF(C21="ALL IN",100000,IF(C21="KEPALA SHIFT",105000,IF(C21="KABAG",110000))))+(I21*IF(C21="ALL IN",200000,IF(C21="KEPALA SHIFT",210000,IF(C21="KABAG",220000)))) -> 0 | N21: =CEILING(SUM(K21:L21),100)-SUM(K21:L21) -> 0 | P21: =SUM(J21:O21) -> 0
A22: =A21+1 -> 18 | B22: EDI SUPARMAN | C22: ALL IN | D22: =VLOOKUP(B22,'[1]GAJI 25 JULI - 24 AGST 2022'!C$9:D$42,2,0) -> OPERATOR CETAK | J22: =(E22*15000) -> 0 | K22: =(F22*IF(C22="ALL IN",50000,IF(C22="KEPALA SHIFT",52500,IF(C22="KABAG",55000))))+(G22*IF(C22="ALL IN",100000,IF(C22="KEPALA SHIFT",105000,IF(C22="KABAG",110000)))) -> 0 | L22: =(H22*IF(C22="ALL IN",100000,IF(C22="KEPALA SHIFT",105000,IF(C22="KABAG",110000))))+(I22*IF(C22="ALL IN",200000,IF(C22="KEPALA SHIFT",210000,IF(C22="KABAG",220000)))) -> 0 | N22: =CEILING(SUM(K22:L22),100)-SUM(K22:L22) -> 0 | P22: =SUM(J22:O22) -> 0
A23: =A22+1 -> 19 | B23: BAYU SETIYAWAN | C23: ALL IN | D23: =VLOOKUP(B23,'[1]GAJI 25 JULI - 24 AGST 2022'!C$9:D$42,2,0) -> MANDOR SCREEN | J23: =(E23*15000) -> 0 | K23: =(F23*IF(C23="ALL IN",50000,IF(C23="KEPALA SHIFT",52500,IF(C23="KABAG",55000))))+(G23*IF(C23="ALL IN",100000,IF(C23="KEPALA SHIFT",105000,IF(C23="KABAG",110000)))) -> 0 | L23: =(H23*IF(C23="ALL IN",100000,IF(C23="KEPALA SHIFT",105000,IF(C23="KABAG",110000))))+(I23*IF(C23="ALL IN",200000,IF(C23="KEPALA SHIFT",210000,IF(C23="KABAG",220000)))) -> 0 | N23: =CEILING(SUM(K23:L23),100)-SUM(K23:L23) -> 0 | P23: =SUM(J23:O23) -> 0
A24: =A23+1 -> 20 | B24: DIAN SULISTYO | C24: ALL IN | D24: =VLOOKUP(B24,'[1]GAJI 25 JULI - 24 AGST 2022'!C$9:D$42,2,0) -> DESIGN | J24: =(E24*15000) -> 0 | K24: =(F24*IF(C24="ALL IN",50000,IF(C24="KEPALA SHIFT",52500,IF(C24="KABAG",55000))))+(G24*IF(C24="ALL IN",100000,IF(C24="KEPALA SHIFT",105000,IF(C24="KABAG",110000)))) -> 0 | L24: =(H24*IF(C24="ALL IN",100000,IF(C24="KEPALA SHIFT",105000,IF(C24="KABAG",110000))))+(I24*IF(C24="ALL IN",200000,IF(C24="KEPALA SHIFT",210000,IF(C24="KABAG",220000)))) -> 0 | N24: =CEILING(SUM(K24:L24),100)-SUM(K24:L24) -> 0 | P24: =SUM(J24:O24) -> 0
A25: =A24+1 -> 21 | B25: ONG KRISTIN | C25: ALL IN | D25: ADM HRD | J25: =(E25*15000) -> 0 | K25: =(F25*IF(C25="ALL IN",50000,IF(C25="KEPALA SHIFT",52500)))+(G25*IF(C25="ALL IN",100000,IF(C25="KEPALA SHIFT",110000))) -> 0 | L25: =(H25*IF(C25="ALL IN",100000,IF(C25="KEPALA SHIFT",105000)))+(I25*IF(C25="ALL IN",200000,IF(C25="KEPALA SHIFT",210000))) -> 0 | N25: =CEILING(SUM(K25:L25),100)-SUM(K25:L25) -> 0 | P25: =SUM(J25:O25) -> 0
A26: =A25+1 -> 22 | B26: NOVI ISTIANI | C26: ALL IN | D26: ADM HRD | J26: =(E26*15000) -> 0 | K26: =(F26*IF(C26="ALL IN",50000,IF(C26="KEPALA SHIFT",52500)))+(G26*IF(C26="ALL IN",100000,IF(C26="KEPALA SHIFT",110000))) -> 0 | L26: =(H26*IF(C26="ALL IN",100000,IF(C26="KEPALA SHIFT",105000)))+(I26*IF(C26="ALL IN",200000,IF(C26="KEPALA SHIFT",210000))) -> 0 | N26: =CEILING(SUM(K26:L26),100)-SUM(K26:L26) -> 0 | P26: =SUM(J26:O26) -> 0
A27: =A26+1 -> 23 | B27: AGUS GUNARDI | C27: ALL IN | D27: DESIGN | J27: =(E27*15000) -> 0 | K27: =(F27*IF(C27="ALL IN",50000,IF(C27="KEPALA SHIFT",52500)))+(G27*IF(C27="ALL IN",100000,IF(C27="KEPALA SHIFT",110000))) -> 0 | L27: =(H27*IF(C27="ALL IN",100000,IF(C27="KEPALA SHIFT",105000)))+(I27*IF(C27="ALL IN",200000,IF(C27="KEPALA SHIFT",210000))) -> 0 | N27: =CEILING(SUM(K27:L27),100)-SUM(K27:L27) -> 0 | P27: =SUM(J27:O27) -> 0
A28: =A27+1 -> 24 | B28: JAIS | D28: DRIVER | N28: =CEILING(SUM(K28:L28),100)-SUM(K28:L28) -> 0 | P28: =SUM(J28:O28) -> 0
A29: =A28+1 -> 25 | B29: SUYONO | D29: DRIVER | N29: =CEILING(SUM(K29:L29),100)-SUM(K29:L29) -> 0 | P29: =SUM(J29:O29) -> 0
A30: =A29+1 -> 26 | B30: MIFTAHUDIN | D30: DRIVER | N30: =CEILING(SUM(K30:L30),100)-SUM(K30:L30) -> 0 | P30: =SUM(J30:O30) -> 0
B32: TOTAL ALL IN | J32: =SUM(J5:J30) -> 0 | K32: =SUM(K5:K30) -> 0 | L32: =SUM(L5:L30) -> 0 | M32: =SUM(M5:M30) -> 0 | N32: =SUM(N5:N30) -> 0 | O32: =SUM(O5:O30) -> 0 | P32: =SUM(P5:P30) -> 0
A35: No | B35: NAMA | E35: UM | F35: LEMBUR TEKNISI | J35: UANG MAKAN | K35: LEMBUR SABTU | L35: LEMBUR MINGGU | M35: INSENTIF | N35: PBLT | O35: REVISI | P35: TOTAL
F36: SABTU | H36: MINGGU
A37: =A30+1 -> 27 | B37: YOHANES PRAYITNO | C37: ALL IN | D37: =VLOOKUP(B37,'[1]GAJI 25 JULI - 24 AGST 2022'!C$9:D$42,2,0) -> UMUM | J37: =(E37*15000) -> 0 | K37: =(F37*(100000/7)) -> 0 | L37: =(H37*(200000/7)) -> 0 | N37: =CEILING(SUM(K37:L37),100)-SUM(K37:L37) -> 0 | P37: =SUM(J37:O37) -> 0
B39: TOTAL UMUM | J39: =SUM(J37) -> 0 | K39: =SUM(K37) -> 0 | L39: =SUM(L37) -> 0 | M39: =SUM(M37) -> 0 | N39: =SUM(N37) -> 0 | O39: =SUM(O37) -> 0 | P39: =SUM(P37) -> 0
B42: TOTAL ALL | J42: =SUM(J39,J32) -> 0 | K42: =SUM(K39,K32) -> 0 | L42: =SUM(L39,L32) -> 0 | M42: =SUM(M39,M32) -> 0 | N42: =SUM(N39,N32) -> 0 | O42: =SUM(O39,O32) -> 0 | P42: =SUM(P39,P32) -> 0

Sheet RESUME GAJI
A1: PT. KEMILAU UNGARAN SUKSES
A4: RESUME GAJI BULAN JUNI 2026
A6: I. KARYAWAN BULANAN
A7: A. ALL IN
A8: No | B8: BAGIAN | C8: JML KARYAWAN | F8: 25 MEI - 24 JUNI 2025 | H8: REVISI | I8: TJ. MASA KERJA | J8: TUNJANGAN | K8: PREMI HADIR | L8: PBLT | M8: TOTAL | N8: LEMBUR | O8: TOTAL + LEMBUR | P8: BPJS TENAGA KERJA | Q8: BPJS KESEHATAN | R8: BPJS PENSIUN | S8: CASHBON | T8: PPH | U8: TOTAL TERIMA
C9: L | D9: P | F9: GAJI
A10: 1 | B10: MANDOR SHIFT | C10: 7 | D10: 0 | E10: =SUM(C10:D10) -> 7 | F10: 20580616 | H10: 0 | I10: 31000 | J10: 950000 | K10: 14210454 | L10: 295.073 | M10: =SUM(F10:K10) -> 35772070 | N10: 0 | O10: =SUM(M10:N10) -> 35772070 | P10: -431232.32 | Q10: -215616.16 | R10: -215616.16 | S10: 0 | T10: 0 | U10: =SUM(L10,M10,N10,P10,Q10,R10,S10,T10) -> 34909900
A11: =A10+1 -> 2 | B11: MANDOR SCREEN | C11: 2 | D11: 0 | E11: =SUM(C11:D11) -> 2 | F11: 5880176 | H11: 0 | I11: 10000 | J11: 300000 | K11: 4797700.6 | L11: 130.473 | M11: =SUM(F11:K11) -> 10987877 | N11: 0 | O11: =SUM(M11:N11) -> 10987877 | P11: -123803.52 | Q11: -61901.76 | R11: -61901.76 | S11: 0 | T11: 0 | U11: =SUM(L11,M11,N11,P11,Q11,R11,S11,T11) -> 10740400
A12: =A11+1 -> 3 | B12: TINTA | C12: 1 | D12: 0 | E12: =SUM(C12:D12) -> 1 | F12: 2940088 | H12: 0 | I12: 5000 | J12: 50000 | K12: 2190165.6 | L12: 49.953 | M12: =SUM(F12:K12) -> 5185253.6 | N12: 0 | O12: =SUM(M12:N12) -> 5185253.6 | P12: -59901.76 | Q12: -29950.88 | R12: -29950.88 | S12: 0 | T12: 0 | U12: =SUM(L12,M12,N12,P12,Q12,R12,S12,T12) -> 5065500
A13: =A12+1 -> 4 | B13: QC PRINT | C13: 0 | D13: 2 | E13: =SUM(C13:D13) -> 2 | F13: 5880176 | H13: 0 | I13: 10000 | J13: 200000 | K13: 3186159.4 | L13: 71.665 | M13: =SUM(F13:K13) -> 9276335.4 | N13: 0 | O13: =SUM(M13:N13) -> 9276335.4 | P13: -121803.52 | Q13: -60901.76 | R13: -60901.76 | S13: 0 | T13: 0 | U13: =SUM(L13,M13,N13,P13,Q13,R13,S13,T13) -> 9032800
A14: =A13+1 -> 5 | B14: IN-OUT | C14: 0 | D14: 1 | E14: =SUM(C14:D14) -> 1 | F14: 2940088 | H14: 0 | I14: 5000 | J14: 0 | K14: 1280274.4 | L14: 41.145 | M14: =SUM(F14:K14) -> 4225362.4 | N14: 0 | O14: =SUM(M14:N14) -> 4225362.4 | P14: -58901.76 | Q14: -29450.88 | R14: -29450.88 | S14: 0 | T14: 0 | U14: =SUM(L14,M14,N14,P14,Q14,R14,S14,T14) -> 4107600
A15: =A14+1 -> 6 | B15: ADM | C15: 0 | D15: 1 | E15: =SUM(C15:D15) -> 1 | F15: 2940088 | H15: 0 | I15: 5000 | J15: 0 | K15: 1280274.4 | L15: 41.145 | M15: =SUM(F15:K15) -> 4225362.4 | N15: 0 | O15: =SUM(M15:N15) -> 4225362.4 | P15: -58901.76 | Q15: -29450.88 | R15: -29450.88 | S15: 0 | T15: 0 | U15: =SUM(L15,M15,N15,P15,Q15,R15,S15,T15) -> 4107600
A16: =A15+1 -> 7 | B16: GUDANG | C16: 0 | D16: 1 | E16: =SUM(C16:D16) -> 1 | F16: 2940088 | H16: 0 | I16: 5000 | J16: 0 | K16: 1073674.4 | L16: 41.145 | M16: =SUM(F16:K16) -> 4018762.4 | N16: 0 | O16: =SUM(M16:N16) -> 4018762.4 | P16: -58901.76 | Q16: -29450.88 | R16: -29450.88 | S16: 0 | T16: 0 | U16: =SUM(L16,M16,N16,P16,Q16,R16,S16,T16) -> 3901000
A17: =A16+1 -> 8 | B17: SAMPLE | C17: 2 | D17: 1 | E17: =SUM(C17:D17) -> 3 | F17: 8920264 | H17: 0 | I17: 14000 | J17: 300000 | K17: 5513412 | L17: 94.56 | M17: =SUM(F17:K17) -> 14747676 | N17: 0 | O17: =SUM(M17:N17) -> 14747676 | P17: -184685.28 | Q17: -92342.64 | R17: -92342.64 | S17: 0 | T17: 0 | U17: =SUM(L17,M17,N17,P17,Q17,R17,S17,T17) -> 14378400
A18: =A17+1 -> 9 | B18: FOLLOW UP | C18: 0 | D18: 0 | E18: =SUM(C18:D18) -> 0 | F18: 0 | H18: 0 | I18: 0 | J18: 0 | K18: 0 | L18: 0 | M18: =SUM(F18:K18) -> 0 | N18: 0 | O18: =SUM(M18:N18) -> 0 | P18: 0 | Q18: 0 | R18: 0 | S18: 0 | T18: 0 | U18: =SUM(L18,M18,N18,P18,Q18,R18,S18,T18) -> 0
A19: =A18+1 -> 10 | B19: OPERATOR CETAK | C19: 1 | D19: 0 | E19: =SUM(C19:D19) -> 1 | F19: 2940088 | H19: 0 | I19: 5000 | J19: 0 | K19: 1905885 | L19: 30.52 | M19: =SUM(F19:K19) -> 4850973 | N19: 0 | O19: =SUM(M19:N19) -> 4850973 | P19: -58901.76 | Q19: -29450.88 | R19: -29450.88 | S19: 0 | T19: 0 | U19: =SUM(L19,M19,N19,P19,Q19,R19,S19,T19) -> 4733200
A20: =A19+1 -> 11 | B20: SECURITY | C20: 0 | D20: 0 | E20: =SUM(C20:D20) -> 0 | F20: 0 | H20: 0 | I20: 0 | J20: 0 | K20: 0 | L20: 0 | M20: =SUM(F20:K20) -> 0 | N20: 0 | O20: =SUM(M20:N20) -> 0 | P20: 0 | Q20: 0 | R20: 0 | S20: 0 | T20: 0 | U20: =SUM(L20,M20,N20,P20,Q20,R20,S20,T20) -> 0
A21: =A20+1 -> 12 | B21: PRESS | C21: 0 | D21: 0 | E21: =SUM(C21:D21) -> 0 | F21: 0 | H21: 0 | I21: 0 | J21: 0 | K21: 0 | L21: 0 | M21: =SUM(F21:K21) -> 0 | N21: 0 | O21: =SUM(M21:N21) -> 0 | P21: 0 | Q21: 0 | R21: 0 | S21: 0 | T21: 0 | U21: =SUM(L21,M21,N21,P21,Q21,R21,S21,T21) -> 0
A22: =A21+1 -> 13 | B22: DRIVER | C22: 3 | D22: 0 | E22: =SUM(C22:D22) -> 3 | F22: 8820264 | H22: 0 | I22: 15000 | J22: 0 | K22: 4230503.8 | L22: 118.779 | M22: =SUM(F22:K22) -> 13065768 | N22: 953324 | O22: =SUM(M22:N22) -> 14019092 | P22: -176705.28 | Q22: -88352.64 | R22: -88352.64 | S22: -1000000 | T22: 0 | U22: =SUM(L22,M22,N22,P22,Q22,R22,S22,T22) -> 12665800
... A26: =A25+1 -> 17 | B26: ADM HRD | C26: 0 | D26: 2 | E26: =SUM(C26:D26) -> 2 | F26: 5880176 | H26: 0 | I26: 7000 | J26: 0 | K26: 2038024 | L26: 87.04 | M26: =SUM(F26:K26) -> 7925200 | N26: 0 | O26: =SUM(M26:N26) -> 7925200 | P26: -117743.52 | Q26: -58871.76 | R26: -58871.76 | S26: 0 | T26: 0 | U26: =SUM(L26,M26,N26,P26,Q26,R26,S26,T26) -> 7689800
B28: TOTAL BULANAN | C28: =SUM(C10:C26) -> 18 | D28: =SUM(D10:D26) -> 8 | F28: =SUM(F10:F26) -> 82286128 | G28: =SUM(G10:G26) -> 0 | H28: =SUM(H10:H26) -> 0 | I28: =SUM(I10:I26) -> 119000 | J28: =SUM(J10:J26) -> 2050000 | K28: =SUM(K10:K26) -> 45176784 | L28: =SUM(L10:L26) -> 1102.738 | M28: =SUM(M10:M26) -> 1.2963191e+08 | ... U28: =SUM(U10:U26) -> 126445387
C29: =SUM(C28:D28) -> 26 | F29: ='[2]GAJI 25 MEI - 24 JUNI 2026'!R42 -> 82286128 | G29: 0 | H29: ='[2]GAJI 25 MEI - 24 JUNI 2026'!T42 -> 0 | I29: ='[2]GAJI 25 MEI - 24 JUNI 2026'!N42 -> 119000 | J29: ='[2]GAJI 25 MEI - 24 JUNI 2026'!U42 -> 2050000 | K29: ='[2]GAJI 25 MEI - 24 JUNI 2026'!V42 -> 45176784 | L29: ='[2]GAJI 25 MEI - 24 JUNI 2026'!W42 -> 1102.738 | M29: ='[2]GAJI 25 MEI - 24 JUNI 2026'!X42-'[2]GAJI 25 MEI - 24 JUNI 2026'!S42 -> 1.2963191e+08 | N29: ='[2]GAJI 25 MEI - 24 JUNI 2026'!S42 -> 953324 | O29: ='[2]GAJI 25 MEI - 24 JUNI 2026'!X42 -> 1.3058524e+08 | P29: ='[2]GAJI 25 MEI - 24 JUNI 2026'!Y42 -> -1569225.8 | Q29: ='[2]GAJI 25 MEI - 24 JUNI 2026'!Z42 -> -784612.88 | R29: ='[2]GAJI 25 MEI - 24 JUNI 2026'!AA42 -> -784612.88 | S29: ='[2]GAJI 25 MEI - 24 JUNI 2026'!AB42 -> -1002500 | T29: ='[2]GAJI 25 MEI - 24 JUNI 2026'!AC42 -> 0 | U29: ='[2]GAJI 25 MEI - 24 JUNI 2026'!AD42 -> 126445387
F30: =F29-F28 -> 0 | G30: =G29-G28 -> 0 | H30: =H29-H28 -> 0 | I30: =I29-I28 -> 0 | J30: =J29-J28 -> 0 | K30: =K29-K28 -> 0 | L30: =L29-L28 -> 0 | M30: =M29-M28 -> 0 | P30: =P29-P28 -> 0 | Q30: =Q29-Q28 -> 0 | R30: =R29-R28 -> 0 | S30: =S29-S28 -> 0 | T30: =T29-T28 -> 0 | U30: =U29-U28 -> 0
A32: B. BULANAN PRINT
A33: No | B33: BAGIAN | C33: JML KARYAWAN | F33: =F8 -> 25 MEI - 24 JUNI 2025 | H33: REVISI | I33: TJ. MASA KERJA | J33: TUNJANGAN JABATAN | K33: PREMI HADIR | L33: PBLT | M33: TOTAL | N33: LEMBUR | O33: TOTAL + LEMBUR | P33: BPJS TENAGA KERJA | Q33: BPJS KESEHATAN | R33: BPJS PENSIUN | S33: CASHBON | T33: PPH | U33: TOTAL TERIMA
C34: L | D34: P | F34: GAJI
A35: 1 | B35: SCREEN | C35: 5 | D35: 0 | E35: =SUM(C35:D35) -> 5 | F35: 14700440 | H35: 0 | I35: 9000 | J35: 0 | K35: 0 | L35: 437.6 | M35: =SUM(F35:K35) -> 14709440 | N35: 5756500 | O35: =SUM(M35:N35) -> 20465940 | P35: -294188.8 | Q35: -147094.4 | R35: -147094.4 | S35: 0 | T35: 0 | U35: =SUM(L35,M35,N35,P35,Q35,R35,S35,T35) -> 19878000
A36: =A35+1 -> 2 | B36: GUDANG PRINT | C36: 0 | D36: 1 | E36: =SUM(C36:D36) -> 1 | F36: 2940088 | H36: 0 | I36: 5000 | J36: 0 | K36: 0 | L36: 15.52 | M36: =SUM(F36:K36) -> 2945088 | N36: 0 | O36: =SUM(M36:N36) -> 2945088 | P36: -58901.76 | Q36: -29450.88 | R36: -29450.88 | S36: 0 | T36: 0 | U36: =SUM(L36,M36,N36,P36,Q36,R36,S36,T36) -> 2827300
A37: =A36+1 -> 3 | B37: SAMPLE | C37: 2 | D37: 8 | E37: =SUM(C37:D37) -> 10 | F37: 28930466 | H37: 0 | I37: 26000 | J37: 0 | K37: 750000 | L37: 582.24 | M37: =SUM(F37:K37) -> 29706466 | N37: 10734600 | O37: =SUM(M37:N37) -> 40441066 | P37: -470774.08 | Q37: -235387.04 | R37: -235387.04 | S37: 0 | T37: 0 | U37: =SUM(L37,M37,N37,P37,Q37,R37,S37,T37) -> 39500100
A38: =A37+1 -> 4 | B38: KURIR | C38: 0 | D38: 0 | E38: =SUM(C38:D38) -> 0 | F38: 0 | H38: 0 | I38: 0 | J38: 0 | K38: 0 | L38: 0 | M38: =SUM(F38:K38) -> 0 | N38: 0 | O38: =SUM(M38:N38) -> 0 | P38: 0 | Q38: 0 | R38: 0 | S38: 0 | T38: 0 | U38: =SUM(L38,M38,N38,P38,Q38,R38,S38,T38) -> 0
A39: =A38+1 -> 5 | B39: ADM HRD | C39: 0 | D39: 0 | E39: =SUM(C39:D39) -> 0 | F39: 0 | H39: 0 | I39: 0 | J39: 0 | K39: 0 | L39: 0 | M39: =SUM(F39:K39) -> 0 | N39: 0 | O39: =SUM(M39:N39) -> 0 | P39: 0 | Q39: 0 | R39: 0 | S39: 0 | T39: 0 | U39: =SUM(L39,M39,N39,P39,Q39,R39,S39,T39) -> 0
A40: =A39+1 -> 6 | B40: UMUM | C40: 1 | D40: 1 | E40: =SUM(C40:D40) -> 2 | F40: 5880176 | H40: 0 | I40: 6000 | J40: 0 | K40: 0 | L40: 67.52 | M40: =SUM(F40:K40) -> 5886176 | N40: 102200 | O40: =SUM(M40:N40) -> 5988376 | P40: -58821.76 | Q40: -29410.88 | R40: -29410.88 | S40: 0 | T40: 0 | U40: =SUM(L40,M40,N40,P40,Q40,R40,S40,T40) -> 5870800
A41: =A40+1 -> 7 | B41: DESIGN | C41: 2 | D41: 0 | E41: =SUM(C41:D41) -> 2 | F41: 5644969 | H41: 0 | I41: 8000 | J41: 0 | K41: 1152000 | L41: 94.56 | M41: =SUM(F41:K41) -> 6804969 | N41: 408500 | O41: =SUM(M41:N41) -> 7213469 | P41: -58881.76 | Q41: -29440.88 | R41: -29440.88 | S41: 0 | T41: 0 | U41: =SUM(L41,M41,N41,P41,Q41,R41,S41,T41) -> 7095800
A42: =A41+1 -> 8 | B42: TINTA | C42: 3 | D42: 0 | E42: =SUM(C42:D42) -> 3 | F42: 8820264 | H42: 0 | I42: 6000 | J42: 0 | K42: 0 | L42: 286.56 | M42: =SUM(F42:K42) -> 8826264 | N42: 3554500 | O42: =SUM(M42:N42) -> 12380764 | P42: -176525.28 | Q42: -88262.64 | R42: -88262.64 | S42: 0 | T42: 0 | U42: =SUM(L42,M42,N42,P42,Q42,R42,S42,T42) -> 12028000
A43: =A42+1 -> 9 | B43: LAB | C43: 1 | D43: 0 | E43: =SUM(C43:D43) -> 1 | F43: 2940088 | H43: 0 | I43: 3000 | J43: 0 | K43: 600000 | L43: 35.52 | M43: =SUM(F43:K43) -> 3543088 | N43: 1497100 | O43: =SUM(M43:N43) -> 5040188 | P43: -58861.76 | Q43: -29430.88 | R43: -29430.88 | S43: 0 | T43: 0 | U43: =SUM(L43,M43,N43,P43,Q43,R43,S43,T43) -> 4922500
A44: =A43+1 -> 10 | B44: PRESS | C44: 1 | D44: 0 | E44: =SUM(C44:D44) -> 1 | F44: 2940088 | H44: 0 | I44: 0 | J44: 0 | K44: 0 | L44: 15.52 | M44: =SUM(F44:K44) -> 2940088 | N44: 399400 | O44: =SUM(M44:N44) -> 3339488 | P44: -58801.76 | Q44: -29400.88 | R44: -29400.88 | S44: 0 | T44: 0 | U44: =SUM(L44,M44,N44,P44,Q44,R44,S44,T44) -> 3221900
A45: =A44+1 -> 11 | B45: PACKING | C45: 0 | D45: 9 | E45: =SUM(C45:D45) -> 9 | F45: 26460792 | H45: 0 | I45: 15000 | J45: 0 | K45: 0 | L45: 739.68 | M45: =SUM(F45:K45) -> 26475792 | N45: 10347700 | O45: =SUM(M45:N45) -> 36823492 | P45: -529515.84 | Q45: -264757.92 | R45: -264757.92 | S45: 0 | T45: 0 | U45: =SUM(L45,M45,N45,P45,Q45,R45,S45,T45) -> 35765200
A46: =A45+1 -> 12 | B46: SECURITY | C46: 4 | D46: 0 | E46: =SUM(C46:D46) -> 4 | F46: 11760352 | H46: 0 | I46: 9000 | J46: 0 | K46: 0 | L46: 222.08 | M46: =SUM(F46:K46) -> 11769352 | N46: 5213300 | O46: =SUM(M46:N46) -> 16982652 | P46: -235387.04 | Q46: -117693.52 | R46: -117693.52 | S46: 0 | T46: 0 | U46: =SUM(L46,M46,N46,P46,Q46,R46,S46,T46) -> 16512100
A47: =A46+1 -> 13 | B47: QC LINE | C47: 0 | D47: 10 | E47: =SUM(C47:D47) -> 10 | F47: 29400880 | H47: 0 | I47: 20000 | J47: 0 | K47: 0 | L47: 955.2 | M47: =SUM(F47:K47) -> 29420880 | N47: 11479800 | O47: =SUM(M47:N47) -> 40900680 | P47: -588417.6 | Q47: -294208.8 | R47: -294208.8 | S47: 0 | T47: 0 | U47: =SUM(L47,M47,N47,P47,Q47,R47,S47,T47) -> 39724800
... A52: =A51+1 -> 18 | B52: SUBLIM | C52: 4 | D52: 8 | E52: =SUM(C52:D52) -> 12 | F52: 25637567 | H52: 0 | I52: 6000 | J52: 0 | K52: 0 | L52: 303.44 | M52: =SUM(F52:K52) -> 25643567 | N52: 3035000 | O52: =SUM(M52:N52) -> 28678567 | P52: -529335.84 | Q52: -235267.04 | R52: -264667.92 | S52: 0 | T52: 0 | U52: =SUM(L52,M52,N52,P52,Q52,R52,S52,T52) -> 27649600
...
